Workbook

Sheet Compras
A1: Producto | B1: Fecha | C1: Documento | D1: N° Documento | E1: Neto | F1: IVA | G1: Total | H1: Mes | I1: Año | K1: Estado | L1: Venta | N1: Neto | O1: IVA | P1: Total
A2: Dominio cl | C2: Factura | D2: 2605941 | H2: =MONTH(M2) -> 12 | I2: =YEAR(M2) -> 2020 | M2: 44169 | N2: 8361.34 | O2: =N2*0.19 -> 1588.6546 | P2: =N2+O2 -> 9949.9946
A3: Importadora y exportadora coreapartes (Kixx) | C3: Factura | D3: 8600 | H3: =MONTH(M3) -> 12 | I3: =YEAR(M3) -> 2020 | M3: 44182 | N3: 34100 | O3: =N3*0.19 -> 6479 | P3: =N3+O3 -> 40579 | R3: =SUM(P2:P8) -> 423651.93
A4: CRL Mobil | C4: Factura | D4: 25216 | H4: =MONTH(M4) -> 12 | I4: =YEAR(M4) -> 2020 | K4: 45990 | L4: 119 | M4: 44186 | N4: 160200 | O4: =N4*0.19 -> 30438 | P4: =N4+O4 -> 190638
A5: El Castillo | C5: Factura | D5: 78733 | H5: =MONTH(M5) -> 12 | I5: =YEAR(M5) -> 2020 | K5: =K4*L5/L4 -> 38647.059 | L5: 100 | M5: 44189 | N5: 4537.815 | O5: =N5*0.19 -> 862.18485 | P5: =N5+O5 -> 5399.9998
A6: CRL Mobil | C6: Factura | D6: 25300 | H6: =MONTH(M6) -> 12 | I6: =YEAR(M6) -> 2020 | M6: 44188 | N6: 84537.815 | O6: =N6*0.19 -> 16062.185 | P6: =N6+O6 -> 100600
A7: Mining Parts SpA | C7: Factura | D7: 1723 | H7: =MONTH(M7) -> 12 | I7: =YEAR(M7) -> 2020 | M7: 44193 | N7: 25626 | O7: =N7*0.19 -> 4868.94 | P7: =N7+O7 -> 30494.94
A8: Angie SpA | C8: Factura | D8: 6132 | H8: =MONTH(M8) -> 12 | I8: =YEAR(M8) -> 2020 | M8: 44194 | N8: 38647.058 | O8: =N8*0.19 -> 7342.941 | P8: =N8+O8 -> 45989.999
A9: Mobil Special 20w-50 4L | B9: 44228 | C9: Factura | D9: 26088 | E9: 32700 | F9: =E9*0.19 -> 6213 | G9: =E9+F9 -> 38913 | H9: =MONTH(B9) -> 2 | I9: =YEAR(B9) -> 2021
A10: Mobilube HD Plus 80w-90 1L | B10: 44229 | C10: Factura | D10: 26098 | E10: 31100 | F10: =E10*0.19 -> 5909 | G10: =E10+F10 -> 37009 | H10: =MONTH(B10) -> 2 | I10: =YEAR(B10) -> 2021
A11: Piola embrague Partner 1.9 2006 | B11: 44235 | C11: Factura | D11: 577557 | E11: 44792 | F11: =E11*0.19 -> 8510.48 | G11: =E11+F11 -> 53302.48 | H11: =MONTH(B11) -> 2 | I11: =YEAR(B11) -> 2021
A12: Faroles traseros Peugeot 206 | B12: 44237 | C12: Factura | D12: 15130 | E12: 43530 | F12: =E12*0.19 -> 8270.7 | G12: =E12+F12 -> 51800.7 | H12: =MONTH(B12) -> 2 | I12: =YEAR(B12) -> 2021
A13: Starken | B13: 44239 | C13: Factura | D13: 9998094 | E13: 3748 | F13: =E13*0.19 -> 712.12 | G13: =E13+F13 -> 4460.12 | H13: =MONTH(B13) -> 2 | I13: =YEAR(B13) -> 2021
A14: Compra Autotec SA | B14: 44245 | C14: Factura | D14: 200722 | E14: 69980 | F14: =E14*0.19 -> 13296.2 | G14: =E14+F14 -> 83276.2 | H14: =MONTH(B14) -> 2 | I14: =YEAR(B14) -> 2021
A15: Luces H4 R11 12000 lm | B15: 44259 | C15: Factura | D15: 806511 | F15: =E15*0.19 -> 0 | G15: =E15+F15 -> 0 | H15: =MONTH(B15) -> 3 | I15: =YEAR(B15) -> 2021
A16: Luces H4 R11 12000 lm | B16: 44268 | C16: Factura | D16: 808881 | F16: =E16*0.19 -> 0 | G16: =E16+F16 -> 0 | H16: =MONTH(B16) -> 3 | I16: =YEAR(B16) -> 2021
A17: Luces H7 y H11 C6 5500 lm | B17: 44269 | C17: Factura | D17: 9926 | F17: =E17*0.19 -> 0 | G17: =E17+F17 -> 0 | H17: =MONTH(B17) -> 3 | I17: =YEAR(B17) -> 2021
A18: Luces H4 C6 5500 lm | B18: 44269 | C18: Factura | D18: 9928 | F18: =E18*0.19 -> 0 | G18: =E18+F18 -> 0 | H18: =MONTH(B18) -> 3 | I18: =YEAR(B18) -> 2021
A19: Ma. Soto-Tapabarro y ópticos | B19: 44272 | C19: Factura | D19: 251966 | E19: 74621 | F19: =E19*0.19 -> 14177.99 | G19: =E19+F19 -> 88798.99 | H19: =MONTH(B19) -> 3 | I19: =YEAR(B19) -> 2021
A20: Varmontt | B20: 44277 | C20: Factura | D20: 470394 | E20: 5782 | F20: =E20*0.19 -> 1098.58 | G20: =E20+F20 -> 6880.58 | H20: =MONTH(B20) -> 3 | I20: =YEAR(B20) -> 2021
A21: Luces H4 R11 12000 lm | B21: 44274 | C21: Factura | D21: 845644 | F21: =E21*0.19 -> 0 | G21: =E21+F21 -> 0 | H21: =MONTH(B21) -> 3 | I21: =YEAR(B21) -> 2021
A22: Starken | B22: 44274 | C22: Factura | D22: 10048137 | E22: 3639 | F22: =E22*0.19 -> 691.41 | G22: =E22+F22 -> 4330.41 | H22: =MONTH(B22) -> 3 | I22: =YEAR(B22) -> 2021
A23: Repuesto Fiat Uno | B23: 44274 | F23: =E23*0.19 -> 0 | G23: 1990 | H23: =MONTH(B23) -> 3 | I23: =YEAR(B23) -> 2021
A24: Filtros petróleo - aire L200 | B24: 44286 | C24: Factura | D24: 16059 | E24: 8236 | F24: =E24*0.19 -> 1564.84 | G24: =E24+F24 -> 9800.84 | H24: =MONTH(B24) -> 3 | I24: =YEAR(B24) -> 2021
A25: Ópticos Hyundai Accent 2010 alt | B25: 44291 | C25: Factura | D25: 253876 | E25: 33446 | F25: =E25*0.19 -> 6354.74 | G25: =E25+F25 -> 39800.74 | H25: =MONTH(B25) -> 4 | I25: =YEAR(B25) -> 2021
A26: Varmontt | B26: 44294 | C26: Factura | D26: 477356 | E26: 4420 | F26: =E26*0.19 -> 839.8 | G26: =E26+F26 -> 5259.8 | H26: =MONTH(B26) -> 4 | I26: =YEAR(B26) -> 2021
A27: Ópticos Hyundai Accent 2009 alt + Pastillas morning 2016 | B27: 44299 | C27: Factura | D27: 254784 | E27: 66975 | F27: =E27*0.19 -> 12725.25 | G27: =E27+F27 -> 79700.25 | H27: =MONTH(B27) -> 4 | I27: =YEAR(B27) -> 2021
A28: Varmontt | B28: 44301 | C28: Factura | D28: 480029 | E28: 4420 | F28: =E28*0.19 -> 839.8 | G28: =E28+F28 -> 5259.8 | H28: =MONTH(B28) -> 4 | I28: =YEAR(B28) -> 2021
A29: CRL Mobil | B29: 44306 | C29: Factura | D29: 27553 | E29: 151500 | F29: =E29*0.19 -> 28785 | G29: =E29+F29 -> 180285 | H29: =MONTH(B29) -> 4 | I29: =YEAR(B29) -> 2021
A30: Alarmas Nemesis Gold | B30: 44318 | C30: Factura | D30: 858888 | E30: 33244 | F30: =E30*0.19 -> 6316.36 | G30: =E30+F30 -> 39560.36 | H30: =MONTH(B30) -> 5 | I30: =YEAR(B30) -> 2021
A31: Luces H4, H7, H11 C6S | B31: 44319 | C31: Factura | D31: 10455 | F31: =E31*0.19 -> 0 | G31: =E31+F31 -> 0 | H31: =MONTH(B31) -> 5 | I31: =YEAR(B31) -> 2021 | J31: 34000
A32: Papel térmico | B32: 44323 | C32: Factura | D32: 999 | E32: 5880 | F32: =E32*0.19 -> 1117.2 | G32: =E32+F32 -> 6997.2 | H32: =MONTH(B32) -> 5 | I32: =YEAR(B32) -> 2021
A33: Luces H4, H11 CS6 | B33: 44326 | C33: Factura | D33: 10538 | F33: =E33*0.19 -> 0 | G33: =E33+F33 -> 0 | H33: =MONTH(B33) -> 5 | I33: =YEAR(B33) -> 2021 | J33: 40800
A34: Par focos led neblineros | B34: 44326 | C34: Factura | D34: 36034 | F34: =E34*0.19 -> 0 | G34: =E34+F34 -> 0 | H34: =MONTH(B34) -> 5 | I34: =YEAR(B34) -> 2021 | J34: 18990 | L34: 19990 | M34: 119
A35: Luces H4 R11 12000 lm | B35: 44326 | C35: Factura | D35: 2929 | F35: =E35*0.19 -> 0 | G35: =E35+F35 -> 0 | H35: =MONTH(B35) -> 5 | I35: =YEAR(B35) -> 2021 | J35: 35160 | L35: =M35*L34/M34 -> 16798.319 | M35: 100
A36: Filtros Ssangyong - Santelices | B36: 44325 | C36: Boleta | E36: 15126 | F36: =E36*0.19 -> 2873.94 | G36: =E36+F36 -> 17999.94 | H36: =MONTH(B36) -> 5 | I36: =YEAR(B36) -> 2021
A37: Filtros Catalán | B37: 44323 | C37: Factura | D37: 16652 | E37: 36639 | F37: =E37*0.19 -> 6961.41 | G37: =E37+F37 -> 43600.41 | H37: =MONTH(B37) -> 5 | I37: =YEAR(B37) -> 2021
A38: Filtros Catalán | B38: 44326 | C38: Nota Crédito | D38: 8021 | E38: -20000 | F38: =E38*0.19 -> -3800 | G38: =E38+F38 -> -23800 | H38: =MONTH(B38) -> 5 | I38: =YEAR(B38) -> 2021
A39: Filtro Suzuki An 125 | B39: 44330 | E39: 6568 | F39: =E39*0.19 -> 1247.92 | G39: =E39+F39 -> 7815.92 | H39: =MONTH(B39) -> 5 | I39: =YEAR(B39) -> 2021
A40: CRL Mobil | B40: 44335 | C40: Factura | D40: 27935 | E40: 159200 | F40: =E40*0.19 -> 30248 | G40: =E40+F40 -> 189448 | H40: =MONTH(B40) -> 5 | I40: =YEAR(B40) -> 2021
...

Sheet Ventas
A1: ID | B1: Producto | C1: Fecha | D1: DTE | E1: N. DTE | F1: Neto | G1: IVA | H1: Total | I1: Costo venta | J1: Ganancia Bruta
A2: 1 | B2: Mobil Extra 10w-40 1L | C2: 44201 | D2: Boleta | E2: 2 | F2: 6714 | G2: =F2*0.19 -> 1275.66 | H2: =F2+G2 -> 7989.66 | I2: 5408.35
A3: 2 | B3: 2x Mobil Super 2000 + fitro | C3: 44206 | D3: Factura | E3: 1 | F3: 42017 | G3: =F3*0.19 -> 7983.23 | H3: =F3+G3 -> 50000.23 | I3: 33226
A4: 3 | B4: Mobil Delvac 15w-40 4L, Filtro Mann | C4: 44212 | D4: Factura | E4: 2 | F4: 33193 | G4: =F4*0.19 -> 6306.67 | H4: =F4+G4 -> 39499.67 | I4: 29200.5
A5: 4 | B5: Mobil Special 20w-50 4L, Filtro Mann | C5: 44221 | D5: Boleta | E5: 4 | F5: 15126 | G5: =F5*0.19 -> 2873.94 | H5: =F5+G5 -> 17999.94 | I5: 12728.25
A6: 5 | B6: Special 20w-50 + filtro alto al costo | C6: 44221 | F6: 10275 | G6: =F6*0.19 -> 1952.25 | H6: =F6+G6 -> 12227.25
A7: 6 | B7: Mobil Special 20w-50 4L | C7: 44221 | D7: Boleta | E7: 5 | F7: 11008 | G7: =F7*0.19 -> 2091.52 | H7: =F7+G7 -> 13099.52 | I7: 9728.25
A8: 7 | B8: Mobil Special 20w-50 4L, Filtro Mann | C8: 44224 | D8: Boleta | E8: 6 | F8: 15126 | G8: =F8*0.19 -> 2873.94 | H8: =F8+G8 -> 17999.94 | I8: 12728.25
A9: 8 | B9: Mobil Extra 10w-40 1L | C9: 44227 | D9: Boleta | E9: 7 | F9: 6723 | G9: =F9*0.19 -> 1277.37 | H9: =F9+G9 -> 8000.37 | I9: 5408.35
A10: 9 | B10: Mobilube Plus HD 80w-90 1L | C10: 44229 | D10: Boleta | E10: 8 | F10: 13866 | G10: =F10*0.19 -> 2634.54 | H10: =F10+G10 -> 16500.54 | I10: 9252.25
A11: 10 | B11: Foco trasero izq y derecho Peugeot 206 | C11: 44240 | D11: Boleta | E11: 9 | F11: 57143 | G11: =F11*0.19 -> 10857.17 | H11: =F11+G11 -> 68000.17 | I11: 51801
A12: 11 | B12: Mobil Extra 10w-40 1L | C12: 44240 | D12: Boleta | E12: 10 | F12: 7059 | G12: =F12*0.19 -> 1341.21 | H12: =F12+G12 -> 8400.21 | I12: 5408.35
A13: 12 | B13: Special 20w-50, Filtro Mann Racer 97 | C13: 44243 | D13: Boleta | E13: 11 | F13: 15126 | G13: =F13*0.19 -> 2873.94 | H13: =F13+G13 -> 17999.94 | I13: 12728.25
A14: 13 | B14: Filtro Aire Alto | C14: 44256 | F14: 2521 | G14: =F14*0.19 -> 478.99 | H14: =F14+G14 -> 2999.99
A15: 14 | B15: Luces H4 R11 | C15: 44261 | D15: Boleta | E15: 13 | G15: =F15*0.19 -> 0 | H15: =F15+G15 -> 0 | I15: 8800
A16: 15 | B16: Special 20w-50, Filtro Mann W811/80 | C16: 44264 | D16: Boleta | E16: 14 | F16: 15126 | G16: =F16*0.19 -> 2873.94 | H16: =F16+G16 -> 17999.94 | I16: 12728.25
A17: 16 | B17: Luces H4 R11 | C17: 44269 | D17: Boleta | E17: 15 | G17: =F17*0.19 -> 0 | H17: =F17+G17 -> 0 | I17: 8800
A18: 17 | B18: Luces H4 R11 | C18: 44274 | D18: Boleta | E18: 16 | G18: =F18*0.19 -> 0 | H18: =F18+G18 -> 0 | I18: 8800
A19: 18 | B19: Mobil Extra 10w-40 1L | C19: 44274 | D19: Boleta | E19: 17 | F19: 7059 | G19: =F19*0.19 -> 1341.21 | H19: =F19+G19 -> 8400.21 | I19: 5408.35
A20: 19 | B20: Repuesto Fiat Uno | C20: 44274 | H20: 10000
A21: 20 | B21: Tapabarro | C21: 44277 | F21: 41176 | G21: =F21*0.19 -> 7823.44 | H21: =F21+G21 -> 48999.44
A22: 21 | B22: Ópticos RH Accent alternativo | C22: 44277 | D22: Boleta | E22: 20 | F22: 23529 | G22: =F22*0.19 -> 4470.51 | H22: =F22+G22 -> 27999.51 | I22: 26780.37
A23: 22 | B23: Luces H4 R11 | C23: 44278 | D23: Boleta | E23: 18 | G23: =F23*0.19 -> 0 | H23: =F23+G23 -> 0 | I23: 8990
A24: 23 | B24: Special 20w-50, Filtro Mann W67/81 | C24: 44281 | D24: Boleta | E24: 19 | F24: 15126 | G24: =F24*0.19 -> 2873.94 | H24: =F24+G24 -> 17999.94 | I24: 12227.25
A25: 24 | B25: Mobil MX x2 + Kit de Filtros L200 | C25: 44289 | D25: Boleta | E25: 21 | F25: 44034 | G25: =F25*0.19 -> 8366.46 | H25: =F25+G25 -> 52400.46 | I25: 37945.5
A26: 25 | B26: Mobil 4T 20w-50 1L | C26: 44292 | D26: Boleta | F26: 3361 | G26: =F26*0.19 -> 638.59 | H26: =F26+G26 -> 3999.59
A27: 26 | B27: Mobil super 2000, filtro mann w67/80 filtro aire | C27: 44295 | D27: Boleta | E27: 24 | F27: 21008 | G27: =F27*0.19 -> 3991.52 | H27: =F27+G27 -> 24999.52 | I27: 32725
A28: 27 | B28: Ópticos RH y LH alternativos Accent 2010 | C28: 44294 | D28: Boleta | E28: 23 | F28: 50420 | G28: =F28*0.19 -> 9579.8 | H28: =F28+G28 -> 59999.8 | I28: 45060.74
A29: 28 | B29: Luces H4 R11 | C29: 44296 | D29: Boleta | E29: 22 | G29: =F29*0.19 -> 0 | H29: =F29+G29 -> 0 | I29: 8990
A30: 29 | B30: Super 2000 10w-40, Filtro w68/85, Mobilube 80w-90 2L | C30: 44300 | F30: 30252 | G30: =F30*0.19 -> 5747.88 | H30: =F30+G30 -> 35999.88
A31: 30 | B31: Ópticos RH y LH alternativos Accent 2009 | C31: 44301 | D31: Boleta | E31: 25 | F31: 50420 | G31: =F31*0.19 -> 9579.8 | H31: =F31+G31 -> 59999.8 | I31: 45060
A32: 31 | B32: Pastillas del Morning orig. | C32: 44301 | F32: 33529 | G32: =F32*0.19 -> 6370.51 | H32: =F32+G32 -> 39899.51
A33: 32 | B33: 4 x Mobilube Plus HD 80w-90 1L | C33: 44306 | D33: Boleta | E33: 26 | F33: 18487 | G33: =F33*0.19 -> 3512.53 | H33: =F33+G33 -> 21999.53 | I33: 12336.33
A34: 33 | B34: Luces H4 C6S | C34: 44316 | D34: Boleta | E34: 27 | G34: =F34*0.19 -> 0 | H34: =F34+G34 -> 0 | I34: 6800
A35: 34 | B35: Special 20w-50 4L, Filtro W712/22 | C35: 44317 | D35: Boleta | E35: 28 | F35: 15126 | G35: =F35*0.19 -> 2873.94 | H35: =F35+G35 -> 17999.94 | I35: 13655.25
A36: 35 | B36: Kixx 10w-40 4L, Filtro W67/81 | C36: 44317 | D36: Boleta | E36: 29 | F36: 17647 | G36: =F36*0.19 -> 3352.93 | H36: =F36+G36 -> 20999.93 | I36: 13643.75
A37: 36 | B37: Special 20w-50 4L, Filtro W67/80 | C37: 44317 | F37: 11475 | G37: =F37*0.19 -> 2180.25 | H37: =F37+G37 -> 13655.25
A38: 37 | B38: Mobil 4T 20w-50 1L | C38: 44318 | F38: 3361 | G38: =F38*0.19 -> 638.59 | H38: =F38+G38 -> 3999.59
A39: 38 | B39: Filtro aire Spark | C39: 44318 | D39: Boleta | E39: 30 | F39: 4202 | G39: =F39*0.19 -> 798.38 | H39: =F39+G39 -> 5000.38 | I39: 3800
A40: 39 | B40: Ópticos LH Accent alternativo | C40: 44322 | D40: Boleta | E40: 31 | F40: 23529 | G40: =F40*0.19 -> 4470.51 | H40: =F40+G40 -> 27999.51 | I40: 26780.37
...

Sheet Mobil Neto
A1: Producto | B1: Litros | C1: Formato | D1: Precio Neto | E1: IVA | F1: Precio Total | G1: Margen 10% | H1: Margen 20% | I1: Margen 25% | J1: Margen 30% | K1: Margen 35% | L1: Margen 40% | M1: Santelices
A2: Mobilfluid 424 | B2: 19 | C2: Balde | D2: 42800 | E2: =D2*19% -> 8132 | F2: =D2+E2 -> 50932 | G2: =D2*1.1 -> 47080 | H2: =D2*1.2 -> 51360 | I2: =D2*1.25 -> 53500 | J2: =D2*1.3 -> 55640 | K2: =D2*1.35 -> 57780 | L2: =D2*1.4 -> 59920 | M2: 38655
A3: Nuto H68 | B3: 19 | C3: Balde | D3: 25800 | E3: =D3*19% -> 4902 | F3: =D3+E3 -> 30702 | G3: =D3*1.1 -> 28380 | H3: =D3*1.2 -> 30960 | I3: =D3*1.25 -> 32250 | J3: =D3*1.3 -> 33540 | K3: =D3*1.35 -> 34830 | L3: =D3*1.4 -> 36120 | M3: 26891 | O3: Total | P3: =SUM(D2:D9) -> 321919
A4: Mobil Delvac Super 1200 F12 15w-40 | B4: 19 | C4: Balde | D4: 37200 | E4: =D4*19% -> 7068 | F4: =D4+E4 -> 44268 | G4: =D4*1.1 -> 40920 | H4: =D4*1.2 -> 44640 | I4: =D4*1.25 -> 46500 | J4: =D4*1.3 -> 48360 | K4: =D4*1.35 -> 50220 | L4: =D4*1.4 -> 52080 | O4: IVA | P4: =P3*19% -> 61164.61
A5: Mobil Delvac MX 15w-40 | B5: 19 | C5: Balde | D5: 40800 | E5: =D5*19% -> 7752 | F5: =D5+E5 -> 48552 | G5: =D5*1.1 -> 44880 | H5: =D5*1.2 -> 48960 | I5: =D5*1.25 -> 51000 | J5: =D5*1.3 -> 53040 | K5: =D5*1.35 -> 55080 | L5: =D5*1.4 -> 57120 | O5: Total Neto | P5: =SUM(P3:P4) -> 383083.61
A6: Mobil Delvac 1300 Super 15w-40 | B6: 19 | C6: Balde | D6: 44200 | E6: =D6*19% -> 8398 | F6: =D6+E6 -> 52598 | G6: =D6*1.1 -> 48620 | H6: =D6*1.2 -> 53040 | I6: =D6*1.25 -> 55250 | J6: =D6*1.3 -> 57460 | K6: =D6*1.35 -> 59670 | L6: =D6*1.4 -> 61880
A7: Mobil ATF 220 | B7: 19 | C7: Balde | D7: 44000 | E7: =D7*19% -> 8360 | F7: =D7+E7 -> 52360 | G7: =D7*1.1 -> 48400 | H7: =D7*1.2 -> 52800 | I7: =D7*1.25 -> 55000 | J7: =D7*1.3 -> 57200 | K7: =D7*1.35 -> 59400 | L7: =D7*1.4 -> 61600 | M7: 25210
A8: Mobilube HD Plus 80w-90 | B8: 19 | C8: Balde | D8: 42300 | E8: =D8*19% -> 8037 | F8: =D8+E8 -> 50337 | G8: =D8*1.1 -> 46530 | H8: =D8*1.2 -> 50760 | I8: =D8*1.25 -> 52875 | J8: =D8*1.3 -> 54990 | K8: =D8*1.35 -> 57105 | L8: =D8*1.4 -> 59220
A9: Mobilube HD Plus 85w-140 | B9: 19 | C9: Balde | D9: 44819 | E9: =D9*19% -> 8515.61 | F9: =D9+E9 -> 53334.61 | G9: =D9*1.1 -> 49300.9 | H9: =D9*1.2 -> 53782.8 | I9: =D9*1.25 -> 56023.75 | J9: =D9*1.3 -> 58264.7 | K9: =D9*1.35 -> 60505.65 | L9: =D9*1.4 -> 62746.6
A10: Mobil Super 2000 X3 10w-40 | B10: 4 | C10: Bidón | D10: 50800 | E10: =D10*19% -> 9652 | F10: =D10+E10 -> 60452 | G10: =D10*1.1 -> 55880 | H10: =D10*1.2 -> 60960 | I10: =D10*1.25 -> 63500 | J10: =D10*1.3 -> 66040 | K10: =D10*1.35 -> 68580 | L10: =D10*1.4 -> 71120
A11: Mobil Super 2000 X3 10w-40 | B11: 4 | C11: Bidón | D11: =D10/4 -> 12700 | E11: =D11*19% -> 2413 | F11: =D11+E11 -> 15113 | G11: =D11*1.1 -> 13970 | H11: =D11*1.2 -> 15240 | I11: =D11*1.25 -> 15875 | J11: =D11*1.3 -> 16510 | K11: =D11*1.35 -> 17145 | L11: =D11*1.4 -> 17780
A12: Special 10w-40 | B12: 1 | C12: Bidón | D12: 33300 | E12: =D12*19% -> 6327 | F12: =D12+E12 -> 39627 | G12: =D12*1.1 -> 36630 | H12: =D12*1.2 -> 39960 | I12: =D12*1.25 -> 41625 | J12: =D12*1.3 -> 43290 | K12: =D12*1.35 -> 44955 | L12: =D12*1.4 -> 46620
A13: Special 20w-50 | B13: 1 | C13: Bidón | D13: 27800 | E13: =D13*19% -> 5282 | F13: =D13+E13 -> 33082 | G13: =D13*1.1 -> 30580 | H13: =D13*1.2 -> 33360 | I13: =D13*1.25 -> 34750 | J13: =D13*1.3 -> 36140 | K13: =D13*1.35 -> 37530 | L13: =D13*1.4 -> 38920
A14: Mobil Extra 4T 10w-40 | B14: 1 | C14: Botella | D14: 54538 | E14: =D14*19% -> 10362.22 | F14: =D14+E14 -> 64900.22 | G14: =D14*1.1 -> 59991.8 | H14: =D14*1.2 -> 65445.6 | I14: =D14*1.25 -> 68172.5 | J14: =D14*1.3 -> 70899.4 | K14: =D14*1.35 -> 73626.3 | L14: =D14*1.4 -> 76353.2
A15: Mobil Super 4T 20w-50 | B15: 1 | C15: Botella | D15: 30000 | E15: =D15*19% -> 5700 | F15: =D15+E15 -> 35700 | G15: =D15*1.1 -> 33000 | H15: =D15*1.2 -> 36000 | I15: =D15*1.25 -> 37500 | J15: =D15*1.3 -> 39000 | K15: =D15*1.35 -> 40500 | L15: =D15*1.4 -> 42000
A16: Mobil Delvac Super 20w-50 | B16: 4 | C16: Bidón | D16: 36121 | E16: =D16*19% -> 6862.99 | F16: =D16+E16 -> 42983.99 | G16: =D16*1.1 -> 39733.1 | H16: =D16*1.2 -> 43345.2 | I16: =D16*1.25 -> 45151.25 | J16: =D16*1.3 -> 46957.3 | K16: =D16*1.35 -> 48763.35 | L16: =D16*1.4 -> 50569.4
A17: Mobil Special 20w-50 | B17: 4 | C17: Bidón | D17: 32700 | E17: =D17*19% -> 6213 | F17: =D17+E17 -> 38913 | G17: =D17*1.1 -> 35970 | H17: =D17*1.2 -> 39240 | I17: =D17*1.25 -> 40875 | J17: =D17*1.3 -> 42510 | K17: =D17*1.35 -> 44145 | L17: =D17*1.4 -> 45780
Q18: =55640*1.19 -> 66211.6
Q19: =33540*1.19 -> 39912.6

Sheet CxC
A1: ID | B1: Detalle Venta | C1: Tipo DTE | D1: N° DTE | E1: Deuda | F1: Deudor
A2: =IFERROR(__xludf.DUMMYFUNCTION("FILTER(Ventas!A:A,Ventas!M:M=""Pendiente"")"),683) -> 683 | B2: =IFERROR(__xludf.DUMMYFUNCTION("FILTER(Ventas!B:B,Ventas!M:M=""Pendiente"")"),"Repuestos Charade") -> Repuestos Charade | C2: =IFERROR(VLOOKUP(A2,Ventas!A:D,4,0),"") -> Boleta | D2: =IFERROR(VLOOKUP(A2,Ventas!A:E,5,0),"") -> 91381 | E2: {=IFERROR(INDEX(Ventas!E:J,MATCH(C2&D2,Ventas!D:D&Ventas!E:E,0),11),0)} -> 0 | F2: {=IFERROR(INDEX(Ventas!E:J,MATCH(C2&D2,Ventas!D:D&Ventas!E:E,0),12),"")} | H2: Total Deudas
A3: =IFERROR(__xludf.DUMMYFUNCTION("""COMPUTED_VALUE"""),1001) -> 1001 | B3: =IFERROR(__xludf.DUMMYFUNCTION("""COMPUTED_VALUE"""),"Termostato Chery Tiggo 1.6 2009") -> Termostato Chery Tiggo 1.6 2009 | C3: =IFERROR(VLOOKUP(A3,Ventas!A:D,4,0),"") -> Factura | D3: =IFERROR(VLOOKUP(A3,Ventas!A:E,5,0),"") -> 25 | E3: {=IFERROR(INDEX(Ventas!E:J,MATCH(C3&D3,Ventas!D:D&Ventas!E:E,0),11),0)} -> 0 | F3: {=IFERROR(INDEX(Ventas!E:J,MATCH(C3&D3,Ventas!D:D&Ventas!E:E,0),12),"")} | H3: =SUM(E:E) -> 0
A4: =IFERROR(__xludf.DUMMYFUNCTION("""COMPUTED_VALUE"""),1015) -> 1015 | B4: =IFERROR(__xludf.DUMMYFUNCTION("""COMPUTED_VALUE"""),"Ventilador Bora") -> Ventilador Bora | C4: =IFERROR(VLOOKUP(A4,Ventas!A:D,4,0),"") -> Factura | D4: =IFERROR(VLOOKUP(A4,Ventas!A:E,5,0),"") -> 29 | E4: {=IFERROR(INDEX(Ventas!E:J,MATCH(C4&D4,Ventas!D:D&Ventas!E:E,0),11),0)} -> 0 | F4: {=IFERROR(INDEX(Ventas!E:J,MATCH(C4&D4,Ventas!D:D&Ventas!E:E,0),12),"")}
A5: =IFERROR(__xludf.DUMMYFUNCTION("""COMPUTED_VALUE"""),1044) -> 1044 | B5: =IFERROR(__xludf.DUMMYFUNCTION("""COMPUTED_VALUE"""),"UK-8650 filtro aire Honda CRV") -> UK-8650 filtro aire Honda CRV | C5: =IFERROR(VLOOKUP(A5,Ventas!A:D,4,0),"") -> Boleta | D5: =IFERROR(VLOOKUP(A5,Ventas!A:E,5,0),"") -> 91712 | E5: {=IFERROR(INDEX(Ventas!E:J,MATCH(C5&D5,Ventas!D:D&Ventas!E:E,0),11),0)} -> 0 | F5: {=IFERROR(INDEX(Ventas!E:J,MATCH(C5&D5,Ventas!D:D&Ventas!E:E,0),12),"")}
A6: =IFERROR(__xludf.DUMMYFUNCTION("""COMPUTED_VALUE"""),1066) -> 1066 | B6: =IFERROR(__xludf.DUMMYFUNCTION("""COMPUTED_VALUE"""),"CU2358 Filtec") -> CU2358 Filtec | C6: =IFERROR(VLOOKUP(A6,Ventas!A:D,4,0),"") -> Boleta | D6: =IFERROR(VLOOKUP(A6,Ventas!A:E,5,0),"") -> 0 | E6: {=IFERROR(INDEX(Ventas!E:J,MATCH(C6&D6,Ventas!D:D&Ventas!E:E,0),11),0)} -> 0 | F6: {=IFERROR(INDEX(Ventas!E:J,MATCH(C6&D6,Ventas!D:D&Ventas!E:E,0),12),"")}
A7: =IFERROR(__xludf.DUMMYFUNCTION("""COMPUTED_VALUE"""),1076) -> 1076 | B7: =IFERROR(__xludf.DUMMYFUNCTION("""COMPUTED_VALUE"""),"Mannol 5w30 7L, w927/8, c24011, pu835x, motor flush mannol, ceramo, aguacol -3") -> Mannol 5w30 7L, w927/8, c24011, pu835x, motor flush mannol, ceramo, aguacol -3 | C7: =IFERROR(VLOOKUP(A7,Ventas!A:D,4,0),"") -> Boleta | D7: =IFERROR(VLOOKUP(A7,Ventas!A:E,5,0),"") -> 91741 | E7: {=IFERROR(INDEX(Ventas!E:J,MATCH(C7&D7,Ventas!D:D&Ventas!E:E,0),11),0)} -> 0 | F7: {=IFERROR(INDEX(Ventas!E:J,MATCH(C7&D7,Ventas!D:D&Ventas!E:E,0),12),"")}
A8: =IFERROR(__xludf.DUMMYFUNCTION("""COMPUTED_VALUE"""),1106) -> 1106 | B8: =IFERROR(__xludf.DUMMYFUNCTION("""COMPUTED_VALUE"""),"Mannol 10w40 4L, w818/8, c26026, cu2336, led h7 y 9006") -> Mannol 10w40 4L, w818/8, c26026, cu2336, led h7 y 9006 | C8: =IFERROR(VLOOKUP(A8,Ventas!A:D,4,0),"") -> Boleta | D8: =IFERROR(VLOOKUP(A8,Ventas!A:E,5,0),"") -> 91770 | E8: {=IFERROR(INDEX(Ventas!E:J,MATCH(C8&D8,Ventas!D:D&Ventas!E:E,0),11),0)} -> 0 | F8: {=IFERROR(INDEX(Ventas!E:J,MATCH(C8&D8,Ventas!D:D&Ventas!E:E,0),12),"")}
A9: =IFERROR(__xludf.DUMMYFUNCTION("""COMPUTED_VALUE"""),1130) -> 1130 | B9: =IFERROR(__xludf.DUMMYFUNCTION("""COMPUTED_VALUE"""),"Kit embrague y Bujías Bora") -> Kit embrague y Bujías Bora | C9: =IFERROR(VLOOKUP(A9,Ventas!A:D,4,0),"") -> Factura | D9: =IFERROR(VLOOKUP(A9,Ventas!A:E,5,0),"") -> 37 | E9: {=IFERROR(INDEX(Ventas!E:J,MATCH(C9&D9,Ventas!D:D&Ventas!E:E,0),11),0)} -> 0 | F9: {=IFERROR(INDEX(Ventas!E:J,MATCH(C9&D9,Ventas!D:D&Ventas!E:E,0),12),"")}
A10: =IFERROR(__xludf.DUMMYFUNCTION("""COMPUTED_VALUE"""),1134) -> 1134 | B10: =IFERROR(__xludf.DUMMYFUNCTION("""COMPUTED_VALUE"""),"Tapa distribuidor chevy 500") -> Tapa distribuidor chevy 500 | C10: =IFERROR(VLOOKUP(A10,Ventas!A:D,4,0),"") -> Boleta | D10: =IFERROR(VLOOKUP(A10,Ventas!A:E,5,0),"") -> 91794 | E10: {=IFERROR(INDEX(Ventas!E:J,MATCH(C10&D10,Ventas!D:D&Ventas!E:E,0),11),0)} -> 0 | F10: {=IFERROR(INDEX(Ventas!E:J,MATCH(C10&D10,Ventas!D:D&Ventas!E:E,0),12),"")}
A11: =IFERROR(__xludf.DUMMYFUNCTION("""COMPUTED_VALUE"""),1135) -> 1135 | B11: =IFERROR(__xludf.DUMMYFUNCTION("""COMPUTED_VALUE"""),"Olar 20w50 4L, w67/81, c1924") -> Olar 20w50 4L, w67/81, c1924 | C11: =IFERROR(VLOOKUP(A11,Ventas!A:D,4,0),"") -> Boleta | D11: =IFERROR(VLOOKUP(A11,Ventas!A:E,5,0),"") -> 91795 | E11: {=IFERROR(INDEX(Ventas!E:J,MATCH(C11&D11,Ventas!D:D&Ventas!E:E,0),11),0)} -> 0 | F11: {=IFERROR(INDEX(Ventas!E:J,MATCH(C11&D11,Ventas!D:D&Ventas!E:E,0),12),"")}
A12: =IFERROR(__xludf.DUMMYFUNCTION("""COMPUTED_VALUE"""),1148) -> 1148 | B12: =IFERROR(__xludf.DUMMYFUNCTION("""COMPUTED_VALUE"""),"Neumático Aptany RP203 195/50R15 82 V") -> Neumático Aptany RP203 195/50R15 82 V | C12: =IFERROR(VLOOKUP(A12,Ventas!A:D,4,0),"") -> Boleta | D12: =IFERROR(VLOOKUP(A12,Ventas!A:E,5,0),"") -> 91806 | E12: {=IFERROR(INDEX(Ventas!E:J,MATCH(C12&D12,Ventas!D:D&Ventas!E:E,0),11),0)} -> 0 | F12: {=IFERROR(INDEX(Ventas!E:J,MATCH(C12&D12,Ventas!D:D&Ventas!E:E,0),12),"")}
A13: =IFERROR(__xludf.DUMMYFUNCTION("""COMPUTED_VALUE"""),1155) -> 1155 | B13: =IFERROR(__xludf.DUMMYFUNCTION("""COMPUTED_VALUE"""),"Plumillas 20 y 18") -> Plumillas 20 y 18 | C13: =IFERROR(VLOOKUP(A13,Ventas!A:D,4,0),"") -> Boleta | D13: =IFERROR(VLOOKUP(A13,Ventas!A:E,5,0),"") -> 91813 | E13: {=IFERROR(INDEX(Ventas!E:J,MATCH(C13&D13,Ventas!D:D&Ventas!E:E,0),11),0)} -> 0 | F13: {=IFERROR(INDEX(Ventas!E:J,MATCH(C13&D13,Ventas!D:D&Ventas!E:E,0),12),"")}
A14: =IFERROR(__xludf.DUMMYFUNCTION("""COMPUTED_VALUE"""),1167) -> 1167 | B14: =IFERROR(__xludf.DUMMYFUNCTION("""COMPUTED_VALUE"""),"Mobil 1 5w30 4L, w811/80, c28035, cu23019") -> Mobil 1 5w30 4L, w811/80, c28035, cu23019 | C14: =IFERROR(VLOOKUP(A14,Ventas!A:D,4,0),"") -> Boleta | D14: =IFERROR(VLOOKUP(A14,Ventas!A:E,5,0),"") -> 91823 | E14: {=IFERROR(INDEX(Ventas!E:J,MATCH(C14&D14,Ventas!D:D&Ventas!E:E,0),11),0)} -> 0 | F14: {=IFERROR(INDEX(Ventas!E:J,MATCH(C14&D14,Ventas!D:D&Ventas!E:E,0),12),"")}
A15: =IFERROR(__xludf.DUMMYFUNCTION("""COMPUTED_VALUE"""),1191) -> 1191 | B15: =IFERROR(__xludf.DUMMYFUNCTION("""COMPUTED_VALUE"""),"Hyundai Xteer Ultra RV C3 5w30 6L x2") -> Hyundai Xteer Ultra RV C3 5w30 6L x2 | C15: =IFERROR(VLOOKUP(A15,Ventas!A:D,4,0),"") -> Factura | D15: =IFERROR(VLOOKUP(A15,Ventas!A:E,5,0),"") -> 46 | E15: {=IFERROR(INDEX(Ventas!E:J,MATCH(C15&D15,Ventas!D:D&Ventas!E:E,0),11),0)} -> 0 | F15: {=IFERROR(INDEX(Ventas!E:J,MATCH(C15&D15,Ventas!D:D&Ventas!E:E,0),12),"")}
A16: =IFERROR(__xludf.DUMMYFUNCTION("""COMPUTED_VALUE"""),1195) -> 1195 | B16: =IFERROR(__xludf.DUMMYFUNCTION("""COMPUTED_VALUE"""),"Tercel chino") -> Tercel chino | C16: =IFERROR(VLOOKUP(A16,Ventas!A:D,4,0),"") -> Boleta | D16: =IFERROR(VLOOKUP(A16,Ventas!A:E,5,0),"") -> 91846 | E16: {=IFERROR(INDEX(Ventas!E:J,MATCH(C16&D16,Ventas!D:D&Ventas!E:E,0),11),0)} -> 0 | F16: {=IFERROR(INDEX(Ventas!E:J,MATCH(C16&D16,Ventas!D:D&Ventas!E:E,0),12),"")}
A17: =IFERROR(__xludf.DUMMYFUNCTION("""COMPUTED_VALUE"""),1207) -> 1207 | B17: =IFERROR(__xludf.DUMMYFUNCTION("""COMPUTED_VALUE"""),"CU1919") -> CU1919 | C17: =IFERROR(VLOOKUP(A17,Ventas!A:D,4,0),"") -> Boleta | D17: =IFERROR(VLOOKUP(A17,Ventas!A:E,5,0),"") -> 91857 | E17: {=IFERROR(INDEX(Ventas!E:J,MATCH(C17&D17,Ventas!D:D&Ventas!E:E,0),11),0)} -> 0 | F17: {=IFERROR(INDEX(Ventas!E:J,MATCH(C17&D17,Ventas!D:D&Ventas!E:E,0),12),"")}
A18: =IFERROR(__xludf.DUMMYFUNCTION("""COMPUTED_VALUE"""),1216) -> 1216 | B18: =IFERROR(__xludf.DUMMYFUNCTION("""COMPUTED_VALUE"""),"Olar 5w30 7L") -> Olar 5w30 7L | C18: =IFERROR(VLOOKUP(A18,Ventas!A:D,4,0),"") -> Factura | D18: =IFERROR(VLOOKUP(A18,Ventas!A:E,5,0),"") -> 48 | E18: {=IFERROR(INDEX(Ventas!E:J,MATCH(C18&D18,Ventas!D:D&Ventas!E:E,0),11),0)} -> 0 | F18: {=IFERROR(INDEX(Ventas!E:J,MATCH(C18&D18,Ventas!D:D&Ventas!E:E,0),12),"")}
A19: =IFERROR(__xludf.DUMMYFUNCTION("""COMPUTED_VALUE"""),1218) -> 1218 | B19: =IFERROR(__xludf.DUMMYFUNCTION("""COMPUTED_VALUE"""),"Mannol ATF Dexron VI x3") -> Mannol ATF Dexron VI x3 | C19: =IFERROR(VLOOKUP(A19,Ventas!A:D,4,0),"") -> Boleta | D19: =IFERROR(VLOOKUP(A19,Ventas!A:E,5,0),"") -> 91866 | E19: {=IFERROR(INDEX(Ventas!E:J,MATCH(C19&D19,Ventas!D:D&Ventas!E:E,0),11),0)} -> 0 | F19: {=IFERROR(INDEX(Ventas!E:J,MATCH(C19&D19,Ventas!D:D&Ventas!E:E,0),12),"")}
A20: =IFERROR(__xludf.DUMMYFUNCTION("""COMPUTED_VALUE"""),1235) -> 1235 | B20: =IFERROR(__xludf.DUMMYFUNCTION("""COMPUTED_VALUE"""),"Shell 10w40 4L, w719/27") -> Shell 10w40 4L, w719/27 | C20: =IFERROR(VLOOKUP(A20,Ventas!A:D,4,0),"") -> Boleta | D20: =IFERROR(VLOOKUP(A20,Ventas!A:E,5,0),"") -> 91883 | E20: {=IFERROR(INDEX(Ventas!E:J,MATCH(C20&D20,Ventas!D:D&Ventas!E:E,0),11),0)} -> 0 | F20: {=IFERROR(INDEX(Ventas!E:J,MATCH(C20&D20,Ventas!D:D&Ventas!E:E,0),12),"")}
A21: =IFERROR(__xludf.DUMMYFUNCTION("""COMPUTED_VALUE"""),1243) -> 1243 | B21: =IFERROR(__xludf.DUMMYFUNCTION("""COMPUTED_VALUE"""),"Mannol 10w40 4L, w67/80 DGP, c3121, cu22001-2") -> Mannol 10w40 4L, w67/80 DGP, c3121, cu22001-2 | C21: =IFERROR(VLOOKUP(A21,Ventas!A:D,4,0),"") -> Boleta | D21: =IFERROR(VLOOKUP(A21,Ventas!A:E,5,0),"") -> 91891 | E21: {=IFERROR(INDEX(Ventas!E:J,MATCH(C21&D21,Ventas!D:D&Ventas!E:E,0),11),0)} -> 0 | F21: {=IFERROR(INDEX(Ventas!E:J,MATCH(C21&D21,Ventas!D:D&Ventas!E:E,0),12),"")}
A22: =IFERROR(__xludf.DUMMYFUNCTION("""COMPUTED_VALUE"""),1316) -> 1316 | B22: =IFERROR(__xludf.DUMMYFUNCTION("""COMPUTED_VALUE"""),"Olar 5w30 5L, w712/19, Ceramol senfineco") -> Olar 5w30 5L, w712/19, Ceramol senfineco | C22: =IFERROR(VLOOKUP(A22,Ventas!A:D,4,0),"") -> Boleta | D22: =IFERROR(VLOOKUP(A22,Ventas!A:E,5,0),"") -> 91958 | E22: {=IFERROR(INDEX(Ventas!E:J,MATCH(C22&D22,Ventas!D:D&Ventas!E:E,0),11),0)} -> 0 | F22: {=IFERROR(INDEX(Ventas!E:J,MATCH(C22&D22,Ventas!D:D&Ventas!E:E,0),12),"")}
A23: =IFERROR(__xludf.DUMMYFUNCTION("""COMPUTED_VALUE"""),1345) -> 1345 | B23: =IFERROR(__xludf.DUMMYFUNCTION("""COMPUTED_VALUE"""),"Shell 15w40 4L, w68/80 hk, ceramol senfineco") -> Shell 15w40 4L, w68/80 hk, ceramol senfineco | C23: =IFERROR(VLOOKUP(A23,Ventas!A:D,4,0),"") -> Boleta | D23: =IFERROR(VLOOKUP(A23,Ventas!A:E,5,0),"") -> 91982 | E23: {=IFERROR(INDEX(Ventas!E:J,MATCH(C23&D23,Ventas!D:D&Ventas!E:E,0),11),0)} -> 0 | F23: {=IFERROR(INDEX(Ventas!E:J,MATCH(C23&D23,Ventas!D:D&Ventas!E:E,0),12),"")}
A24: =IFERROR(__xludf.DUMMYFUNCTION("""COMPUTED_VALUE"""),1346) -> 1346 | B24: =IFERROR(__xludf.DUMMYFUNCTION("""COMPUTED_VALUE"""),"wolver 5w30 1Lx3,w7023, c22015, cu1910") -> wolver 5w30 1Lx3,w7023, c22015, cu1910 | C24: =IFERROR(VLOOKUP(A24,Ventas!A:D,4,0),"") -> Boleta | D24: =IFERROR(VLOOKUP(A24,Ventas!A:E,5,0),"") -> 91983 | E24: {=IFERROR(INDEX(Ventas!E:J,MATCH(C24&D24,Ventas!D:D&Ventas!E:E,0),11),0)} -> 0 | F24: {=IFERROR(INDEX(Ventas!E:J,MATCH(C24&D24,Ventas!D:D&Ventas!E:E,0),12),"")}
A25: =IFERROR(__xludf.DUMMYFUNCTION("""COMPUTED_VALUE"""),1348) -> 1348 | B25: =IFERROR(__xludf.DUMMYFUNCTION("""COMPUTED_VALUE"""),"Neumaticos Goodride 175/65R14 Hernan") -> Neumaticos Goodride 175/65R14 Hernan | C25: =IFERROR(VLOOKUP(A25,Ventas!A:D,4,0),"") -> Boleta | D25: =IFERROR(VLOOKUP(A25,Ventas!A:E,5,0),"") -> 91986 | E25: {=IFERROR(INDEX(Ventas!E:J,MATCH(C25&D25,Ventas!D:D&Ventas!E:E,0),11),0)} -> 0 | F25: {=IFERROR(INDEX(Ventas!E:J,MATCH(C25&D25,Ventas!D:D&Ventas!E:E,0),12),"")}
A26: =IFERROR(__xludf.DUMMYFUNCTION("""COMPUTED_VALUE"""),1364) -> 1364 | B26: =IFERROR(__xludf.DUMMYFUNCTION("""COMPUTED_VALUE"""),"Liqui Moly 10w40 5L, w7023") -> Liqui Moly 10w40 5L, w7023 | C26: =IFERROR(VLOOKUP(A26,Ventas!A:D,4,0),"") -> Boleta | D26: =IFERROR(VLOOKUP(A26,Ventas!A:E,5,0),"") -> 91999 | E26: {=IFERROR(INDEX(Ventas!E:J,MATCH(C26&D26,Ventas!D:D&Ventas!E:E,0),11),0)} -> 0 | F26: {=IFERROR(INDEX(Ventas!E:J,MATCH(C26&D26,Ventas!D:D&Ventas!E:E,0),12),"")}
A27: =IFERROR(__xludf.DUMMYFUNCTION("""COMPUTED_VALUE"""),1372) -> 1372 | B27: =IFERROR(__xludf.DUMMYFUNCTION("""COMPUTED_VALUE"""),"Shell 15w40 4L, w68/80 hk") -> Shell 15w40 4L, w68/80 hk | C27: =IFERROR(VLOOKUP(A27,Ventas!A:D,4,0),"") -> Boleta | D27: =IFERROR(VLOOKUP(A27,Ventas!A:E,5,0),"") -> 92007 | E27: {=IFERROR(INDEX(Ventas!E:J,MATCH(C27&D27,Ventas!D:D&Ventas!E:E,0),11),0)} -> 0 | F27: {=IFERROR(INDEX(Ventas!E:J,MATCH(C27&D27,Ventas!D:D&Ventas!E:E,0),12),"")}
A28: =IFERROR(__xludf.DUMMYFUNCTION("""COMPUTED_VALUE"""),1396) -> 1396 | B28: =IFERROR(__xludf.DUMMYFUNCTION("""COMPUTED_VALUE"""),"Limpia Inyector Mannol") -> Limpia Inyector Mannol | C28: =IFERROR(VLOOKUP(A28,Ventas!A:D,4,0),"") -> Boleta | D28: =IFERROR(VLOOKUP(A28,Ventas!A:E,5,0),"") -> 92028 | E28: {=IFERROR(INDEX(Ventas!E:J,MATCH(C28&D28,Ventas!D:D&Ventas!E:E,0),11),0)} -> 0 | F28: {=IFERROR(INDEX(Ventas!E:J,MATCH(C28&D28,Ventas!D:D&Ventas!E:E,0),12),"")}
A29: =IFERROR(__xludf.DUMMYFUNCTION("""COMPUTED_VALUE"""),1405) -> 1405 | B29: =IFERROR(__xludf.DUMMYFUNCTION("""COMPUTED_VALUE"""),"Super 2000 4L, w68/80, c2513") -> Super 2000 4L, w68/80, c2513 | C29: =IFERROR(VLOOKUP(A29,Ventas!A:D,4,0),"") -> Boleta | D29: =IFERROR(VLOOKUP(A29,Ventas!A:E,5,0),"") -> 92036 | E29: {=IFERROR(INDEX(Ventas!E:J,MATCH(C29&D29,Ventas!D:D&Ventas!E:E,0),11),0)} -> 0 | F29: {=IFERROR(INDEX(Ventas!E:J,MATCH(C29&D29,Ventas!D:D&Ventas!E:E,0),12),"")}
A30: =IFERROR(__xludf.DUMMYFUNCTION("""COMPUTED_VALUE"""),1406) -> 1406 | B30: =IFERROR(__xludf.DUMMYFUNCTION("""COMPUTED_VALUE"""),"c2860 filtec") -> c2860 filtec | C30: =IFERROR(VLOOKUP(A30,Ventas!A:D,4,0),"") -> Boleta | D30: =IFERROR(VLOOKUP(A30,Ventas!A:E,5,0),"") -> 92037 | E30: {=IFERROR(INDEX(Ventas!E:J,MATCH(C30&D30,Ventas!D:D&Ventas!E:E,0),11),0)} -> 0 | F30: {=IFERROR(INDEX(Ventas!E:J,MATCH(C30&D30,Ventas!D:D&Ventas!E:E,0),12),"")}
A31: =IFERROR(__xludf.DUMMYFUNCTION("""COMPUTED_VALUE"""),1418) -> 1418 | B31: =IFERROR(__xludf.DUMMYFUNCTION("""COMPUTED_VALUE"""),"Bomba de bencina completa chv spark") -> Bomba de bencina completa chv spark | C31: =IFERROR(VLOOKUP(A31,Ventas!A:D,4,0),"") -> Boleta | D31: =IFERROR(VLOOKUP(A31,Ventas!A:E,5,0),"") -> 92048 | E31: {=IFERROR(INDEX(Ventas!E:J,MATCH(C31&D31,Ventas!D:D&Ventas!E:E,0),11),0)} -> 0 | F31: {=IFERROR(INDEX(Ventas!E:J,MATCH(C31&D31,Ventas!D:D&Ventas!E:E,0),12),"")}
A32: =IFERROR(__xludf.DUMMYFUNCTION("""COMPUTED_VALUE"""),1451) -> 1451 | B32: =IFERROR(__xludf.DUMMYFUNCTION("""COMPUTED_VALUE"""),"Mannol Ceramic 5w30 4L, w610/82, filtros jac s4 2020") -> Mannol Ceramic 5w30 4L, w610/82, filtros jac s4 2020 | C32: =IFERROR(VLOOKUP(A32,Ventas!A:D,4,0),"") -> Boleta | D32: =IFERROR(VLOOKUP(A32,Ventas!A:E,5,0),"") -> 92078 | E32: {=IFERROR(INDEX(Ventas!E:J,MATCH(C32&D32,Ventas!D:D&Ventas!E:E,0),11),0)} -> 0 | F32: {=IFERROR(INDEX(Ventas!E:J,MATCH(C32&D32,Ventas!D:D&Ventas!E:E,0),12),"")}
C33: =IFERROR(VLOOKUP(A33,Ventas!A:D,4,0),"") | D33: =IFERROR(VLOOKUP(A33,Ventas!A:E,5,0),"") | E33: {=IFERROR(INDEX(Ventas!E:J,MATCH(C33&D33,Ventas!D:D&Ventas!E:E,0),11),0)} -> 0 | F33: {=IFERROR(INDEX(Ventas!E:J,MATCH(C33&D33,Ventas!D:D&Ventas!E:E,0),12),"")}
C34: =IFERROR(VLOOKUP(A34,Ventas!A:D,4,0),"") | D34: =IFERROR(VLOOKUP(A34,Ventas!A:E,5,0),"") | E34: {=IFERROR(INDEX(Ventas!E:J,MATCH(C34&D34,Ventas!D:D&Ventas!E:E,0),11),0)} -> 0 | F34: {=IFERROR(INDEX(Ventas!E:J,MATCH(C34&D34,Ventas!D:D&Ventas!E:E,0),12),"")}
C35: =IFERROR(VLOOKUP(A35,Ventas!A:D,4,0),"") | D35: =IFERROR(VLOOKUP(A35,Ventas!A:E,5,0),"") | E35: {=IFERROR(INDEX(Ventas!E:J,MATCH(C35&D35,Ventas!D:D&Ventas!E:E,0),11),0)} -> 0 | F35: {=IFERROR(INDEX(Ventas!E:J,MATCH(C35&D35,Ventas!D:D&Ventas!E:E,0),12),"")}
C36: =IFERROR(VLOOKUP(A36,Ventas!A:D,4,0),"") | D36: =IFERROR(VLOOKUP(A36,Ventas!A:E,5,0),"") | E36: {=IFERROR(INDEX(Ventas!E:J,MATCH(C36&D36,Ventas!D:D&Ventas!E:E,0),11),0)} -> 0 | F36: {=IFERROR(INDEX(Ventas!E:J,MATCH(C36&D36,Ventas!D:D&Ventas!E:E,0),12),"")}
C37: =IFERROR(VLOOKUP(A37,Ventas!A:D,4,0),"") | D37: =IFERROR(VLOOKUP(A37,Ventas!A:E,5,0),"") | E37: {=IFERROR(INDEX(Ventas!E:J,MATCH(C37&D37,Ventas!D:D&Ventas!E:E,0),11),0)} -> 0 | F37: {=IFERROR(INDEX(Ventas!E:J,MATCH(C37&D37,Ventas!D:D&Ventas!E:E,0),12),"")}
C38: =IFERROR(VLOOKUP(A38,Ventas!A:D,4,0),"") | D38: =IFERROR(VLOOKUP(A38,Ventas!A:E,5,0),"") | E38: {=IFERROR(INDEX(Ventas!E:J,MATCH(C38&D38,Ventas!D:D&Ventas!E:E,0),11),0)} -> 0 | F38: {=IFERROR(INDEX(Ventas!E:J,MATCH(C38&D38,Ventas!D:D&Ventas!E:E,0),12),"")}
C39: =IFERROR(VLOOKUP(A39,Ventas!A:D,4,0),"") | D39: =IFERROR(VLOOKUP(A39,Ventas!A:E,5,0),"") | E39: {=IFERROR(INDEX(Ventas!E:J,MATCH(C39&D39,Ventas!D:D&Ventas!E:E,0),11),0)} -> 0 | F39: {=IFERROR(INDEX(Ventas!E:J,MATCH(C39&D39,Ventas!D:D&Ventas!E:E,0),12),"")}
C40: =IFERROR(VLOOKUP(A40,Ventas!A:D,4,0),"") | D40: =IFERROR(VLOOKUP(A40,Ventas!A:E,5,0),"") | E40: {=IFERROR(INDEX(Ventas!E:J,MATCH(C40&D40,Ventas!D:D&Ventas!E:E,0),11),0)} -> 0 | F40: {=IFERROR(INDEX(Ventas!E:J,MATCH(C40&D40,Ventas!D:D&Ventas!E:E,0),12),"")}
...
